Workbook

Sheet Tuan19-Học
A1: Tuần 19 | D1: Thứ 2 | I1: Thứ 3 | N1: Thứ 4 | S1: Thứ 5 | X1: Thứ 6 | AB1: Thứ 7 | AF1: Chủ nhật
A2: TT | B2: Phòng | C2: Số sv | D2: Kíp 1 | E2: Kíp 2 | F2: Kíp 3 | G2: Kíp 4 | H2: Kíp 5 | I2: Kíp 1 | J2: Kíp 2 | K2: Kíp 3 | L2: Kíp 4 | M2: Kíp 5 | N2: Kíp 1 | O2: Kíp 2 | P2: Kíp 3 | Q2: Kíp 4 | R2: Kíp 5 | S2: Kíp 1 | T2: Kíp 2 | U2: Kíp 3 | V2: Kíp 4 | W2: Kíp 4 | X2: Kíp 1 | Y2: Kíp 2 | Z2: Kíp 3 | AA2: Kíp 4 | AB2: Kíp 1 | AC2: Kíp 2 | AD2: Kíp 3 | AE2: Kíp 4 | AF2: Kíp 1 | AG2: Kíp 2 | AH2: Kíp 3 | AI2: Kíp 4
A3: 1 | B3: B1-106 | C3: 37 | D3: Học | E3: Học | F3: Học | G3: Học | I3: Học | J3: Học | K3: Học | L3: Học | N3: Học | O3: Học | P3: Học | Q3: Học | S3: Học | T3: Học | U3: Học | V3: Học | W3: Học | X3: Học | Y3: Học | Z3: Học | AA3: Học
A4: 2 | B4: B1-107 | C4: 37 | D4: Học | E4: Học | F4: Học | G4: Học | I4: Học | J4: Học | K4: Học | L4: Học | N4: Học | O4: Học | P4: Học | Q4: Học | S4: Học | T4: Học | U4: Học | V4: Học | W4: Học | X4: Học | Y4: Học | Z4: Học | AA4: Học
A5: 3 | B5: B1-108 | C5: 37 | F5: Học | G5: Học | K5: Học | L5: Học | S5: Học | T5: Học | X5: Học | Y5: Học | Z5: Học | AA5: Học
A6: 4 | B6: B1-109 | C6: 37 | D6: Học | E6: Học | F6: Học | G6: Học | K6: Học | L6: Học | S6: Học | T6: Học
A7: 5 | B7: B1-202 | C7: 37 | I7: Học | J7: Học | K7: Học | L7: Học | N7: Học | O7: Học | P7: Học | Q7: Học | S7: Học | T7: Học | U7: Học | V7: Học | W7: Học
A8: 6 | B8: B1-203 | C8: 30 | I8: Học | J8: Học | K8: Học | L8: Học | N8: Học | O8: Học | P8: Học | Q8: Học | S8: Học | T8: Học | U8: Học | V8: Học | W8: Học | X8: Học | Y8: Học | Z8: Học | AA8: Học
A9: 7 | B9: B1-204 | C9: 37 | D9: Học | E9: Học | F9: Học | G9: Học | I9: Học | J9: Học | K9: Học | L9: Học | N9: Học | O9: Học | P9: Học | Q9: Học | S9: Học | T9: Học | U9: Học | V9: Học | W9: Học | X9: Học | Y9: Học | Z9: Học | AA9: Học
A10: 8 | B10: B1-206 | C10: 37 | D10: Học | E10: Học | F10: Học | G10: Học | K10: Học | L10: Học | P10: Học | Q10: Học | U10: Học | V10: Học | W10: Học | Z10: Học | AA10: Học
A11: 9 | B11: B1-207 | C11: 37 | D11: Học | E11: Học | F11: Học | G11: Học | K11: Học | L11: Học | N11: Học | O11: Học | P11: Học | Q11: Học | S11: Học | T11: Học | U11: Học | V11: Học | W11: Học | X11: Học | Y11: Học | Z11: Học | AA11: Học
A12: 10 | B12: B1-208 | C12: 37 | D12: Học | E12: Học | F12: Học | G12: Học | I12: Học | J12: Học | K12: Học | L12: Học | N12: Học | O12: Học | P12: Học | Q12: Học | X12: Học | Y12: Học | Z12: Học | AA12: Học
A13: 11 | B13: B1-209 | C13: 37 | F13: Học | G13: Học | I13: Học | J13: Học | K13: Học | L13: Học | S13: Học | T13: Học | X13: Học | Y13: Học | Z13: Học | AA13: Học
B14: số lớp học | D14: =COUNTA(D3:D13) -> 7 | E14: =COUNTA(E3:E13) -> 7 | F14: =COUNTA(F3:F13) -> 9 | G14: =COUNTA(G3:G13) -> 9 | H14: =COUNTA(H3:H13) -> 0 | I14: =COUNTA(I3:I13) -> 7 | J14: =COUNTA(J3:J13) -> 7 | K14: =COUNTA(K3:K13) -> 11 | ... AI14: =COUNTA(AI3:AI13) -> 0
B15: Số sv thi | D15: =(11-D14)*37-5 -> 143 | E15: =(11-E14)*37-5 -> 143 | F15: =(11-F14)*37-5 -> 69 | G15: =(11-G14)*37-5 -> 69 | H15: =(11-H14)*37-5 -> 402 | I15: =(11-I14)*37 -> 148 | J15: =(11-J14)*37 -> 148 | K15: =(11-K14)*37 -> 0 | L15: =(11-L14)*37 -> 0 | M15: =(11-M14)*37 -> 407 | N15: =(11-N14)*37 -> 148 | O15: =(11-O14)*37 -> 148 | P15: =(11-P14)*37 -> 111 | ... AA15: =(11-AA14)*37 -> 74 | AB15: =(11-AB14)*37-5 -> 402 | AC15: =(11-AC14)*37-5 -> 402 | AD15: =(11-AD14)*37-5 -> 402 | AE15: =(11-AE14)*37-5 -> 402 | AF15: =(11-AF14)*37-5 -> 402 | AG15: =(11-AG14)*37-5 -> 402 | AH15: =(11-AH14)*37-5 -> 402 | AI15: =(11-AI14)*37-5 -> 402

Sheet TrucKyThuat
A1: TT | B1: Họ và tên | C1: Tuần 20 | D1: Tuần 21 | E1: Tuần 22 | F1: Cộng
A2: 1 | B2: Phạm Thanh Liêm | C2: =COUNTIF(Tuan20!$18:$19,TrucKyThuat!B2) -> 2 | D2: =COUNTIF(Tuan21!$18:$19,TrucKyThuat!B2) -> 1 | E2: =COUNTIF(Tuan22!$18:$19,TrucKyThuat!B2) -> 3 | F2: =SUM(C2:E2) -> 6
A3: 2 | B3: Nguyễn An Hưng | C3: =COUNTIF(Tuan20!$18:$19,TrucKyThuat!B3) -> 0 | D3: =COUNTIF(Tuan21!$18:$19,TrucKyThuat!B3) -> 0 | E3: =COUNTIF(Tuan22!$18:$19,TrucKyThuat!B3) -> 2 | F3: =SUM(C3:E3) -> 2
A4: 3 | B4: Hoàng Văn Hiệp | C4: =COUNTIF(Tuan20!$18:$19,TrucKyThuat!B4) -> 0 | D4: =COUNTIF(Tuan21!$18:$19,TrucKyThuat!B4) -> 0 | E4: =COUNTIF(Tuan22!$18:$19,TrucKyThuat!B4) -> 2 | F4: =SUM(C4:E4) -> 2
A5: 4 | B5: Nguyễn Văn Hiên | C5: =COUNTIF(Tuan20!$18:$19,TrucKyThuat!B5) -> 4 | D5: =COUNTIF(Tuan21!$18:$19,TrucKyThuat!B5) -> 3 | E5: =COUNTIF(Tuan22!$18:$19,TrucKyThuat!B5) -> 2 | F5: =SUM(C5:E5) -> 9
A6: 5 | B6: Phạm Quang Hiếu | C6: =COUNTIF(Tuan20!$18:$19,TrucKyThuat!B6) -> 3 | D6: =COUNTIF(Tuan21!$18:$19,TrucKyThuat!B6) -> 3 | E6: =COUNTIF(Tuan22!$18:$19,TrucKyThuat!B6) -> 3 | F6: =SUM(C6:E6) -> 9
A7: 6 | B7: Phạm Thị Phương Giang | C7: =COUNTIF(Tuan20!$18:$19,TrucKyThuat!B7) -> 0 | D7: =COUNTIF(Tuan21!$18:$19,TrucKyThuat!B7) -> 4 | E7: =COUNTIF(Tuan22!$18:$19,TrucKyThuat!B7) -> 5 | F7: =SUM(C7:E7) -> 9
A8: 7 | B8: Trần Thị Dung | C8: =COUNTIF(Tuan20!$18:$19,TrucKyThuat!B8) -> 3 | D8: =COUNTIF(Tuan21!$18:$19,TrucKyThuat!B8) -> 1 | E8: =COUNTIF(Tuan22!$18:$19,TrucKyThuat!B8) -> 6 | F8: =SUM(C8:E8) -> 10 | G8: IT1130
A9: 8 | B9: Nhữ Thị Nga | C9: =COUNTIF(Tuan20!$18:$19,TrucKyThuat!B9) -> 1 | D9: =COUNTIF(Tuan21!$18:$19,TrucKyThuat!B9) -> 3 | E9: =COUNTIF(Tuan22!$18:$19,TrucKyThuat!B9) -> 6 | F9: =SUM(C9:E9) -> 10 | G9: IT1130
A10: 9 | B10: Lê Thị Hoa | C10: =COUNTIF(Tuan20!$18:$19,TrucKyThuat!B10) -> 4 | D10: =COUNTIF(Tuan21!$18:$19,TrucKyThuat!B10) -> 2 | E10: =COUNTIF(Tuan22!$18:$19,TrucKyThuat!B10) -> 4 | F10: =SUM(C10:E10) -> 10 | G10: IT1130

Sheet Tuan20
A1: Tuần 20 | D1: Thứ 2 (19.01.2025) | I1: Thứ 3 (20.01.2025) | N1: Thứ 4 (21.01.2026) | T1: Thứ 5 (22.01.2026) | Y1: Thứ 6 (23.01.2026) | AD1: Thứ 7 (24.01.2026) | AH1: Chủ nhật (25.01.2026)
A2: TT | B2: Phòng | C2: Số sv | D2: Kíp 1 - 7h00 | E2: Kíp 2-9h30 | F2: Kíp 3-12h30 | G2: Kíp 4-15h00 | H2: Kíp 5-17h30 | I2: Kíp 1 - 7h00 | J2: Kíp 2-9h30 | K2: Kíp 3-12h30 | L2: Kíp 4-15h00 | M2: Kíp 5-17h30 | N2: Kíp 1 - 7h00 | O2: Kíp 2-9h30 | P2: Kíp 3-12h30 | Q2: Kíp 4-15h00 | R2: Kíp 5-17h30 | S2: Kíp 5.2-18h45 | T2: Kíp 1 - 7h00 | U2: Kíp 2-9h30 | V2: Kíp 3-12h30 | W2: Kíp 4-15h00 | X2: Kíp 5-17h30 | Y2: Kíp 1 - 7h00 | Z2: Kíp 2-9h30 | AA2: Kíp 3-12h30 | AB2: Kíp 4-15h00 | AC2: Kíp 5-17h30 | AD2: Kíp 1 | AE2: Kíp 2 | AF2: Kíp 3 | AG2: Kíp 4 | AH2: Kíp 1 | AI2: Kíp 2 | AJ2: Kíp 3 | AK2: Kíp 4
A3: 1 | B3: B1-106 | C3: 37 | D3: IT4409-161623-ThànhNT | E3: IT4409-162307-QuynhPH | F3: IT4082 - HoáTN | H3: IT3180 - 161626 - 190224 | K3: IT3230-Trần Đức Duy | L3: IT3230 | N3: IT3030E - HiepHV | O3: IT3030E - TrungNL | R3: IT3030 - GiangTDK | S3: IT3030 - GiangTDK | T3: IT4772 - HieuNK | V3: IT4172 | W3: IT4043E | X3: IT4172 | Y3: IT3120E | Z3: IT3120E | AC3: IT4735 | AD3: Thi TSA | AH3: Thi TSA
A4: 2 | B4: B1-107 | C4: 37 | D4: IT4409-162308-HuongTT | E4: IT4409-162307-HuongTT | F4: IT4082 - SơnNV | H4: IT3180 - 161626 - 190224 | K4: IT3230-Nguyễn Quốc Tuấn | L4: IT3230 | N4: IT3030E - TienND | O4: IT3030E - TienND | R4: IT3030 - TienND | S4: IT3030 - TienND | V4: IT4172 | W4: IT4043E | X4: IT4172 | Y4: IT3120E | Z4: IT3120E | AC4: IT4735
A5: 3 | B5: B1-108 | C5: 37 | D5: IT4409-162308-LamDB | E5: IT4409-162307-LamDB | F5: IT4082 - TienND | H5: IT3180 - 162271 | K5: IT3230-Lã Thế Vinh | L5: IT3230 | N5: IT3030E - Trần Duy | O5: IT3030E - Trần Duy | R5: IT3030 - NguyênĐS | S5: IT3030 - NguyênĐS | V5: IT4172 | W5: IT4043E | X5: IT4172 | Y5: IT3120E | Z5: IT3120E | AC5: IT4735
A6: 4 | B6: B1-109 | C6: 37 | D6: IT4409-162308-HangNTT | E6: IT4409-162307-HangNTT | F6: IT4082 | H6: IT3180 - 162271 | K6: IT3230-Dương Quang Huy | L6: IT3230 | O6: IT3030E - ThuanDC | R6: IT3030 - LongNH | S6: IT3030 - LongNH | V6: IT4172 | W6: IT4043E | X6: IT4172 | AC6: IT4735
A7: 5 | B7: B1-202 | C7: 37 | D7: IT4409 | F7: IT4082 | H7: IT3180 - 162271 | K7: IT3230-Nguyễn Tiến Thành | L7: IT3230 | M7: IT4441 | R7: IT3030 - QuangNH | V7: IT4172 | X7: IT4172 | AC7: IT4735
A8: 6 | B8: B1-203 -SD Laptop | C8: 30 | H8: IT3180 - 162271 - SơnNV | K8: IT3230-Nguyễn Hồng Phương | L8: IT3230 | AC8: IT4735
A9: 7 | B9: B1-204 | C9: 37 | D9: IT4409-161256 | E9: IT4409-161255 | F9: IT4082 | G9: IT3180-162273-190231 | H9: IT3180 - 162272 - AnhTL | J9: IT4930 | K9: IT3230-Tạ Duy Hoàng | L9: IT3230 | M9: IT4441 | Q9: IT3283E - HungPN | R9: IT3034 - HungPN | S9: IT3030 - HungPN | V9: IT4172 | X9: IT4172 | AA9: IT3220-161472 | AC9: IT4735
A10: 8 | B10: B1-206 | C10: 37 | D10: IT4409-161256 | E10: IT4409-161255 | F10: IT4082 | G10: IT3180-162273-190231 | H10: IT3180 - 162272 - TienND | J10: IT4930 | K10: IT3230-Vũ Đức Vượng | L10: IT3230 | M10: IT4441 | Q10: IT3283E - HuynhDH | R10: IT3030 - HiepHV | S10: IT3030 - HiepHV | V10: IT4172 | X10: IT4172 | AA10: IT3220-161470 | AC10: IT4735
A11: 9 | B11: B1-207 | C11: 37 | D11: IT4409-161256 | E11: IT4409-161255 | F11: IT4082E | G11: IT3180-162273-190232 | H11: IT3180 - 162272 - TrungBQ | J11: IT4930 | K11: IT3230- Ngô Thành Trung | L11: IT3230 | M11: IT4441E | Q11: IT3283E - TienND | R11: IT3030 - TrungLĐ | S11: IT3030 - TrungLĐ | V11: IT4172 | X11: IT4172 | AA11: IT3220-161471 | AC11: IT4735
A12: 10 | B12: B1-208 | C12: 37 | D12: IT4409-161256,161257-DuyTĐ | E12: IT4409-161257-ThànhNT | F12: IT4082E | G12: IT3180-162273-190232 | H12: IT3180 - 162272 - HoáTN | J12: IT4930 | K12: IT3230-Nguyễn Hồng Quang | L12: IT3230 | M12: IT4441E | Q12: IT3283E - HiepHV | R12: IT3030 - TrungNL | S12: IT3030 - HuyNông | V12: IT4172 | X12: IT4172 | AA12: IT3230-161473 | AC12: IT4735
A13: 11 | B13: B1-209 | C13: 37 | D13: IT4409-161257-ĐạtTT | E13: IT4409-161257-ĐạtTT | F13: IT4082E | G13: IT3180-162273-190232 | H13: IT3180 - 162272 | J13: IT4930 | K13: IT3230-Nguyễn Duy Tùng | L13: IT3230 | M13: IT4441E | Q13: IT3283E - LongNH | R13: IT3030 - TrungNThanh | S13: IT3030 - TrungNThanh | V13: IT4172 | X13: IT4172 | AA13: IT5425 | AB13: IT4681 | AC13: IT4735E
D14: =COUNTA(D3:D13) -> 10 | E14: =COUNTA(E3:E13) -> 9 | F14: =COUNTA(Tuan20!F3:F13) -> 10 | G14: =COUNTA(G3:G13) -> 5 | H14: =COUNTA(H3:H13) -> 11 | I14: =COUNTA(I3:I8) -> 0 | J14: =COUNTA(J3:J13) -> 5 | K14: =COUNTA(K3:K13) -> 11 | L14: =COUNTA(L3:L13) -> 11 | M14: =COUNTA(M5:M13) -> 6 | N14: =COUNTA(N3:N13) -> 3 | O14: =COUNTA(O3:O13) -> 4 | P14: =COUNTA(P3:P13) -> 0 | Q14: =COUNTA(Q3:Q13) -> 5 | R14: =COUNTA(R3:R13) -> 10 | T14: =COUNTA(T3:T13) -> 1 | U14: =COUNTA(U3:U13) -> 0 | V14: =COUNTA(V3:V13) -> 10 | W14: =COUNTA(W3:W13) -> 4 | X14: =COUNTA(X3:X13) -> 10 | Y14: =COUNTA(Y3:Y13) -> 3 | Z14: =COUNTA(Z3:Z13) -> 3 | AA14: =COUNTA(AA4:AA13) -> 5 | AC14: =COUNTA(AC3:AC13) -> 11 | AD14: =COUNTA(AD3:AD13) -> 1 | AE14: =COUNTA(AE3:AE13) -> 0 | AF14: =COUNTA(AF3:AF13) -> 0 | AG14: =COUNTA(AG3:AG13) -> 0 | AH14: =COUNTA(AH3:AH13) -> 1 | AI14: =COUNTA(AI3:AI13) -> 0 | AJ14: =COUNTA(AJ3:AJ13) -> 0 | AK14: =COUNTA(AK3:AK13) -> 0
B15: Số sv thi | D15: =(11-D14)*37-5 -> 32 | E15: =(11-E14)*37-5 -> 69 | F15: =(11-F14)*37-5 -> 32 | G15: =(11-G14)*37-5 -> 217 | H15: =(11-H14)*37-5 -> -5 | I15: =(11-I14)*37 -> 407 | J15: =(11-J14)*37 -> 222 | K15: =(11-K14)*37 -> 0 | L15: =(11-L14)*37 -> 0 | M15: =(11-M14)*37 -> 185 | N15: =(11-N14)*37 -> 296 | O15: =(11-O14)*37 -> 259 | P15: =(11-P14)*37 -> 407 | ... R15: =(11-R14)*37 -> 37 | T15: =(11-T14)*37 -> 370 | U15: =(11-U14)*37 -> 407 | V15: =(11-V14)*37 -> 37 | W15: =(11-W14)*37 -> 259 | X15: =(11-X14)*37 -> 37 | Y15: =(11-Y14)*37 -> 296 | Z15: =(11-Z14)*37 -> 296 | AA15: =(11-AA14)*37 -> 222 | AC15: =(11-AC14)*37 -> 0 | AD15: =(11-AD14)*37-5 -> 365 | AE15: =(11-AE14)*37-5 -> 402 | AF15: =(11-AF14)*37-5 -> 402 | AG15: =(11-AG14)*37-5 -> 402 | AH15: =(11-AH14)*37-5 -> 365 | AI15: =(11-AI14)*37-5 -> 402 | AJ15: =(11-AJ14)*37-5 -> 402 | AK15: =(11-AK14)*37-5 -> 402
K16: Thi Hustack
A17: Trực kỹ thuật
B18: Tầng 1 | D18: Phạm Quang Hiếu | F18: Lê Thị Hoa | K18: Trần Thị Dung | N18: Trần Thị Dung | P18: Nguyễn Văn Hiên | T18: Phạm Thanh Liêm | V18: Phạm Quang Hiếu | Y18: Nhữ Thị Nga | AA18: Lê Thị Hoa
B19: Tầng 2 | D19: Lê Thị Hoa | F19: Nguyễn Văn Hiên | I19: Lê Thị Hoa | K19: Phạm Quang Hiếu | L19: Phạm Thanh Liêm | P19: Trần Thị Dung | V19: Nguyễn Văn Hiên | AA19: Nguyễn Văn Hiên
B20: Trực phòng var | D20: Hoàng Việt Dũng

Sheet LichThi_Chung_Note
A1: Mã lớp thi | B1: Mã lớp học | C1: Mã học phần | D1: Tên học phần | E1: Ghi chú | F1: Nhóm | G1: Đợt | H1: Tuần | I1: Thứ | J1: Ngày thi | K1: Kíp thi | L1: SL | M1: Phòng thi | N1: Mã lớp thi | O1: Note | P1: Giảng viên
A2: 189921 | B2: 164907 | C2: IT1108 | D2: Nhập môn lập trình | E2: **Tài năng KHMT-K70C | F2: CTTN-KHMT-K70 | G2: AB | H2: T21 | I2: Thứ hai | J2: 46048 | K2: Kíp 1 | L2: 50 | M2: Phòng máy_Trung tâm máy tính | N2: 189921
A3: 189924 | B3: 165278 | C3: IT1108 | D3: Nhập môn lập trình | E3: KH máy tính 01,02,03,04-K70C | F3: Khoa học máy tính 04-K70 | G3: AB | H3: T21 | I3: Thứ hai | J3: 46048 | K3: Kíp 1 | L3: 40 | M3: Phòng máy_Trung tâm máy tính | N3: 189924
A4: 189922 | B4: 165278 | C4: IT1108 | D4: Nhập môn lập trình | E4: KH máy tính 01,02,03,04-K70C | F4: TC | G4: AB | H4: T21 | I4: Thứ hai | J4: 46048 | K4: Kíp 2 | L4: 20 | M4: Phòng máy_Trung tâm máy tính | N4: 189922
A5: 189926 | B5: 165278 | C5: IT1108 | D5: Nhập môn lập trình | E5: KH máy tính 01,02,03,04-K70C | F5: Khoa học máy tính 02-K70 | G5: AB | H5: T21 | I5: Thứ hai | J5: 46048 | K5: Kíp 1 | L5: 42 | M5: Phòng máy_Trung tâm máy tính | N5: 189926
A6: 189923 | B6: 165278 | C6: IT1108 | D6: Nhập môn lập trình | E6: KH máy tính 01,02,03,04-K70C | F6: Khoa học máy tính 03-K70 | G6: AB | H6: T21 | I6: Thứ hai | J6: 46048 | K6: Kíp 1 | L6: 42 | M6: Phòng máy_Trung tâm máy tính | N6: 189923
A7: 189925 | B7: 165278 | C7: IT1108 | D7: Nhập môn lập trình | E7: KH máy tính 01,02,03,04-K70C | F7: Khoa học máy tính 01-K70 | G7: AB | H7: T21 | I7: Thứ hai | J7: 46048 | K7: Kíp 1 | L7: 40 | M7: Phòng máy_Trung tâm máy tính | N7: 189925
A8: 189929 | B8: 165286 | C8: IT1108 | D8: Nhập môn lập trình | E8: KH máy tính 05,06,07 - KT máy tính 05-K70S | F8: Khoa học máy tính 07-K70 | G8: AB | H8: T21 | I8: Thứ hai | J8: 46048 | K8: Kíp 1 | L8: 40 | M8: Phòng máy_Trung tâm máy tính | N8: 189929
A9: 189928 | B9: 165286 | C9: IT1108 | D9: Nhập môn lập trình | E9: KH máy tính 05,06,07 - KT máy tính 05-K70S | F9: TC | G9: AB | H9: T21 | I9: Thứ hai | J9: 46048 | K9: Kíp 2 | L9: 12 | M9: Phòng máy_Trung tâm máy tính | N9: 189928
A10: 189927 | B10: 165286 | C10: IT1108 | D10: Nhập môn lập trình | E10: KH máy tính 05,06,07 - KT máy tính 05-K70S | F10: Khoa học máy tính 05-K70 | G10: AB | H10: T21 | I10: Thứ hai | J10: 46048 | K10: Kíp 1 | L10: 41 | M10: Phòng máy_Trung tâm máy tính | N10: 189927
A11: 189931 | B11: 165286 | C11: IT1108 | D11: Nhập môn lập trình | E11: KH máy tính 05,06,07 - KT máy tính 05-K70S | F11: Kỹ thuật máy tính 05-K70 | G11: AB | H11: T21 | I11: Thứ hai | J11: 46048 | K11: Kíp 1 | L11: 44 | M11: Phòng máy_Trung tâm máy tính | N11: 189931
A12: 189930 | B12: 165286 | C12: IT1108 | D12: Nhập môn lập trình | E12: KH máy tính 05,06,07 - KT máy tính 05-K70S | F12: Khoa học máy tính 06-K70 | G12: AB | H12: T21 | I12: Thứ hai | J12: 46048 | K12: Kíp 1 | L12: 41 | M12: Phòng máy_Trung tâm máy tính | N12: 189930
A13: 189935 | B13: 165293 | C13: IT1108 | D13: Nhập môn lập trình | E13: KT máy tính 01,02,03,04-K70S | F13: Kỹ thuật máy tính 01-K70 | G13: AB | H13: T21 | I13: Thứ hai | J13: 46048 | K13: Kíp 2 | L13: 44 | M13: Phòng máy_Trung tâm máy tính | N13: 189935
... A188: 190233 | B188: 162273 | C188: IT3180 | D188: Nhập môn công nghệ phần mềm | E188: (Blend)-KH máy tính - KT máy tính-K68C | F188: Nhóm 1 | G188: AB | H188: T20 | I188: Thứ hai | J188: 46041 | K188: Kíp 5 | L188: 54 | M188: Phòng máy_Trung tâm máy tính | N188: 190233
A189: 190232 | B189: 162273 | C189: IT3180 | D189: Nhập môn công nghệ phần mềm | E189: (Blend)-KH máy tính - KT máy tính-K68C | F189: Nhóm 2 | G189: AB | H189: T20 | I189: Thứ hai | J189: 46041 | K189: Kíp 3 | L189: 53 | M189: Phòng máy_Trung tâm máy tính | N189: 190232 | O189: kíp 3 xin chuyển kíp 4 | P189: GiangVTH
A190: 190231 | B190: 162273 | C190: IT3180 | D190: Nhập môn công nghệ phần mềm | E190: (Blend)-KH máy tính - KT máy tính-K68C | F190: Nhóm 3 | G190: AB | H190: T20 | I190: Thứ hai | J190: 46041 | K190: Kíp 4 | L190: 53 | M190: Phòng máy_Trung tâm máy tính | N190: 190231
A191: 190239 | B191: 162268 | C191: IT3190 | D191: Nhập môn Học máy và khai phá dữ liệu | E191: KH máy tính-K68S | F191: Nhóm 2 | G191: AB | H191: T21 | I191: Thứ hai | J191: 46048 | K191: Kíp 3 | L191: 46 | M191: Phòng máy_Trung tâm máy tính | N191: 190239
A192: 190238 | B192: 162268 | C192: IT3190 | D192: Nhập môn Học máy và khai phá dữ liệu | E192: KH máy tính-K68S | F192: Nhóm 1 | G192: AB | H192: T21 | I192: Thứ hai | J192: 46048 | K192: Kíp 3 | L192: 46 | M192: Phòng máy_Trung tâm máy tính | N192: 190238
A193: 190241 | B193: 162269 | C193: IT3190 | D193: Nhập môn Học máy và khai phá dữ liệu | E193: KH máy tính-K68S | F193: Nhóm 1 | G193: AB | H193: T21 | I193: Thứ hai | J193: 46048 | K193: Kíp 3 | L193: 50 | M193: Phòng máy_Trung tâm máy tính | N193: 190241
A194: 190240 | B194: 162269 | C194: IT3190 | D194: Nhập môn Học máy và khai phá dữ liệu | E194: KH máy tính-K68S | F194: Nhóm 2 | G194: AB | H194: T21 | I194: Thứ hai | J194: 46048 | K194: Kíp 3 | L194: 49 | M194: Phòng máy_Trung tâm máy tính | N194: 190240
A195: 190242 | B195: 164865 | C195: IT3190 | D195: Nhập môn Học máy và khai phá dữ liệu | E195: KSCS-GenAI - Khối kiến thức ngành rộng | F195: TC | G195: AB | H195: T21 | I195: Thứ hai | J195: 46048 | K195: Kíp 3 | L195: 25 | M195: Phòng máy_Trung tâm máy tính | N195: 190242
A196: 190272 | B196: 161861 | C196: IT3320E | D196: Introduction to Deep Learning | E196: **CTTT-Data Science, An toàn KG-K68C | F196: TC | G196: AB | H196: T20 | I196: Thứ ba | J196: 46042 | K196: Kíp 1 | L196: 71 | M196: Phòng máy_Trung tâm máy tính | N196: 190272
A197: 190274 | B197: 161862 | C197: IT3320E | D197: Introduction to Deep Learning | E197: **CTTT-Data Science, An toàn KG-K68C | F197: Nhóm 2 | G197: AB | H197: T20 | I197: Thứ ba | J197: 46042 | K197: Kíp 1 | L197: 40 | M197: Phòng máy_Trung tâm máy tính | N197: 190274
A198: 190273 | B198: 161862 | C198: IT3320E | D198: Introduction to Deep Learning | E198: **CTTT-Data Science, An toàn KG-K68C | F198: Nhóm 1 | G198: AB | H198: T20 | I198: Thứ ba | J198: 46042 | K198: Kíp 1 | L198: 40 | M198: Phòng máy_Trung tâm máy tính | N198: 190273
A199: 190330 | B199: 161857 | C199: IT4010E | D199: Nhập môn an toàn thông tin | E199: **CTTT-Data Science, An toàn KG-K68C | F199: Nhóm 1 | G199: AB | H199: T22 | I199: Thứ sáu | J199: 46059 | K199: Kíp 3 | L199: 47 | M199: Phòng máy_Trung tâm máy tính | N199: 190330
A200: 190331 | B200: 161857 | C200: IT4010E | D200: Nhập môn an toàn thông tin | E200: **CTTT-Data Science, An toàn KG-K68C | F200: Nhóm 2 | G200: AB | H200: T22 | I200: Thứ sáu | J200: 46059 | K200: Kíp 3 | L200: 50 | M200: Phòng máy_Trung tâm máy tính | N200: 190331
A201: 190332 | B201: 161858 | C201: IT4010E | D201: Nhập môn an toàn thông tin | E201: **CTTT-Data Science, An toàn KG-K68C | F201: Nhóm 2 | G201: AB | H201: T22 | I201: Thứ sáu | J201: 46059 | K201: Kíp 3 | L201: 49 | M201: Phòng máy_Trung tâm máy tính | N201: 190332
... A279: 190600 | B279: 162267 | C279: IT5425 | D279: Quản trị dữ liệu và trực quan hóa | E279: KH máy tính-K68S | F279: TC | G279: AB | H279: T20 | I279: Thứ sáu | J279: 46045 | K279: Kíp 3 | L279: 37 | M279: Phòng máy_Trung tâm máy tính | N279: 190600
A280: 190467 | B280: 161250 | C280: IT4651 | D280: Thiết kế và triển khai mạng IP | E280: *Việt Nhật K67C | F280: Nhóm 1 | G280: VN_ICT | H280: T21 | I280: Thứ sáu | J280: 46052 | K280: Kíp 4 | L280: 43 | M280: Phòng máy TTMT | N280: 190467 | P280: Phạm Huy Hoàng | Q280: 670 | R280: 43 | S280: AB | T280: 674 | U280: Elitech | V280: TCNTT | W280: Trường Công nghệ thông tin và Truyền thông | X280: 190467 | Y280: D9-501 | Z280: 67 | AA280: Phạm Huy Hoàng | AB280: Thi trên máy tính | AC280: X | AD280: Phạm Huy Hoàng
A281: 190468 | B281: 161250 | C281: IT4651 | D281: Thiết kế và triển khai mạng IP | E281: *Việt Nhật K67C | F281: Nhóm 2 | G281: VN_ICT | H281: T21 | I281: Thứ sáu | J281: 46052 | K281: Kíp 4 | L281: 42 | M281: Phòng máy TTMT | N281: 190468 | P281: Phạm Huy Hoàng | Q281: 670 | R281: 42 | S281: AB | T281: 674 | U281: Elitech | V281: TCNTT | W281: Trường Công nghệ thông tin và Truyền thông | X281: 190468 | Y281: D9-501 | Z281: 67 | AA281: Phạm Huy Hoàng | AB281: Thi trên máy tính | AC281: X | AD281: Phạm Huy Hoàng
A282: 190489 | B282: 161251 | C282: IT4785 | D282: Phát triển ứng dụng cho thiết bị di động | E282: *Việt Nhật K67-1C | F282: Nhóm 2 | G282: VN_ICT | H282: T22 | I282: Thứ hai | J282: 46055 | K282: Kíp 3,5 | L282: 51 | M282: Phòng máy TTMT | N282: 190489 | P282: Lê Bá Vui | Q282: 670 | R282: 51 | S282: AB | T282: 674 | U282: Elitech | V282: TCNTT | W282: Trường Công nghệ thông tin và Truyền thông | X282: 190489 | Y282: D9-501 | Z282: 67 | AA282: Lê Bá Vui | AB282: Thi trên máy tính | AC282: X | AD282: Hoàng Văn Hiệp
A283: 190490 | B283: 161251 | C283: IT4785 | D283: Phát triển ứng dụng cho thiết bị di động | E283: *Việt Nhật K67-1C | F283: Nhóm 3 | G283: VN_ICT | H283: T22 | I283: Thứ hai | J283: 46055 | K283: Kíp 3,5 | L283: 51 | M283: Phòng máy TTMT | N283: 190490 | P283: Lê Bá Vui | Q283: 670 | R283: 51 | S283: AB | T283: 674 | U283: Elitech | V283: TCNTT | W283: Trường Công nghệ thông tin và Truyền thông | X283: 190490 | Y283: D9-501 | Z283: 67 | AA283: Lê Bá Vui | AB283: Thi trên máy tính | AC283: X | AD283: Hoàng Văn Hiệp
A284: 190491 | B284: 161251 | C284: IT4785 | D284: Phát triển ứng dụng cho thiết bị di động | E284: *Việt Nhật K67-1C | F284: Nhóm 1 | G284: VN_ICT | H284: T22 | I284: Thứ hai | J284: 46055 | K284: Kíp 3,5 | L284: 52 | M284: Phòng máy TTMT | N284: 190491 | P284: Lê Bá Vui | Q284: 670 | R284: 52 | S284: AB | T284: 674 | U284: Elitech | V284: TCNTT | W284: Trường Công nghệ thông tin và Truyền thông | X284: 190491 | Y284: D9-501 | Z284: 67 | AA284: Lê Bá Vui | AB284: Thi trên máy tính | AC284: X | AD284: Hoàng Văn Hiệp
A285: 190493 | B285: 161252 | C285: IT4785 | D285: Phát triển ứng dụng cho thiết bị di động | E285: *Việt Nhật K67-2C | F285: Nhóm 1 | G285: VN_ICT | H285: T22 | I285: Thứ hai | J285: 46055 | K285: Kíp 3,5 | L285: 47 | M285: Phòng máy TTMT | N285: 190493 | P285: Nguyễn Đình Thuận | Q285: 670 | R285: 47 | S285: AB | T285: 674 | U285: Elitech | V285: TCNTT | W285: Trường Công nghệ thông tin và Truyền thông | X285: 190493 | Y285: D9-501 | Z285: 67 | AA285: Nguyễn Đình Thuận | AB285: Thi trên máy tính | AC285: X | AD285: Hoàng Văn Hiệp
A286: 190492 | B286: 161252 | C286: IT4785 | D286: Phát triển ứng dụng cho thiết bị di động | E286: *Việt Nhật K67-2C | F286: Nhóm 2 | G286: VN_ICT | H286: T22 | I286: Thứ hai | J286: 46055 | K286: Kíp 3,5 | L286: 47 | M286: Phòng máy TTMT | N286: 190492 | P286: Nguyễn Đình Thuận | Q286: 670 | R286: 47 | S286: AB | T286: 674 | U286: Elitech | V286: TCNTT | W286: Trường Công nghệ thông tin và Truyền thông | X286: 190492 | Y286: D9-501 | Z286: 67 | AA286: Nguyễn Đình Thuận | AB286: Thi trên máy tính | AC286: X | AD286: Hoàng Văn Hiệp
A287: 190494 | B287: 161252 | C287: IT4785 | D287: Phát triển ứng dụng cho thiết bị di động | E287: *Việt Nhật K67-2C | F287: Nhóm 3 | G287: VN_ICT | H287: T22 | I287: Thứ hai | J287: 46055 | K287: Kíp 3,5 | L287: 47 | M287: Phòng máy TTMT | N287: 190494 | P287: Nguyễn Đình Thuận | Q287: 670 | R287: 47 | S287: AB | T287: 674 | U287: Elitech | V287: TCNTT | W287: Trường Công nghệ thông tin và Truyền thông | X287: 190494 | Y287: D9-501 | Z287: 67 | AA287: Nguyễn Đình Thuận | AB287: Thi trên máy tính | AC287: X | AD287: Hoàng Văn Hiệp
A288: 190235 | B288: 161253 | C288: IT3190 | D288: Nhập môn Học máy và khai phá dữ liệu | E288: *Việt Nhật K67-1C | F288: Nhóm 1 | G288: VN_ICT | H288: T21 | I288: Thứ hai | J288: 46048 | K288: Kíp 3,4 | L288: 60 | M288: Phòng máy TTMT | N288: 190235 | P288: Nguyễn Thị Kim Anh | Q288: 670 | R288: 60 | S288: AB | T288: 674 | U288: Elitech | V288: TCNTT | W288: Trường Công nghệ thông tin và Truyền thông | X288: 190235 | Y288: D9-501 | Z288: 67 | AA288: Nguyễn Thị Kim Anh | AB288: Thi trên máy tính | AC288: X | AD288: Thân Quang Khoát
A289: 190234 | B289: 161253 | C289: IT3190 | D289: Nhập môn Học máy và khai phá dữ liệu | E289: *Việt Nhật K67-1C | F289: Nhóm 2 | G289: VN_ICT | H289: T21 | I289: Thứ hai | J289: 46048 | K289: Kíp 3,4 | L289: 60 | M289: Phòng máy TTMT | N289: 190234 | P289: Nguyễn Thị Kim Anh | Q289: 670 | R289: 60 | S289: AB | T289: 674 | U289: Elitech | V289: TCNTT | W289: Trường Công nghệ thông tin và Truyền thông | X289: 190234 | Y289: D9-501 | Z289: 67 | AA289: Nguyễn Thị Kim Anh | AB289: Thi trên máy tính | AC289: X | AD289: Thân Quang Khoát
A290: 190237 | B290: 161254 | C290: IT3190 | D290: Nhập môn Học máy và khai phá dữ liệu | E290: *Việt Nhật K67-2C | F290: Nhóm 2 | G290: VN_ICT | H290: T21 | I290: Thứ hai | J290: 46048 | K290: Kíp 3,4 | L290: 65 | M290: Phòng máy TTMT | N290: 190237 | P290: Đỗ Tiến Dũng | Q290: 670 | R290: 65 | S290: AB | T290: 674 | U290: Elitech | V290: TCNTT | W290: Trường Công nghệ thông tin và Truyền thông | X290: 190237 | Y290: D9-501 | Z290: 67 | AA290: Đỗ Tiến Dũng | AB290: Thi trên máy tính | AC290: X | AD290: Thân Quang Khoát
A291: 190236 | B291: 161254 | C291: IT3190 | D291: Nhập môn Học máy và khai phá dữ liệu | E291: *Việt Nhật K67-2C | F291: Nhóm 1 | G291: VN_ICT | H291: T21 | I291: Thứ hai | J291: 46048 | K291: Kíp 3,4 | L291: 66 | M291: Phòng máy TTMT | N291: 190236 | P291: Đỗ Tiến Dũng | Q291: 670 | R291: 66 | S291: AB | T291: 674 | U291: Elitech | V291: TCNTT | W291: Trường Công nghệ thông tin và Truyền thông | X291: 190236 | Y291: D9-501 | Z291: 67 | AA291: Đỗ Tiến Dũng | AB291: Thi trên máy tính | AC291: X | AD291: Thân Quang Khoát
...

Sheet VN_ICT_24.12
A1: Mã lớp thi | B1: Mã lớp QT | C1: primaryclassid | D1: Mã HP | E1: Tên học phần | F1: Ghi chú | G1: studyGroupID | H1: Nhóm | I1: Tuần | J1: Thứ | K1: Ngày | L1: Kíp thi | M1: Phòng | N1: sessionid | O1: SLĐK | P1: Đợt mở | Q1: ManagerID | R1: Mã_QL | S1: TeachUnitID | T1: Name | U1: Mã lớp thi | V1: Phòng học | W1: Khóa
A2: 190467 | B2: 161250 | C2: 161250 | D2: IT4651 | E2: Thiết kế và triển khai mạng IP | F2: *Việt Nhật K67C | G2: 130 | H2: Nhóm 1 | I2: T21 | J2: Thứ sáu | K2: 46052 | L2: Kíp 4 | M2: Phòng máy TTMT | N2: 670 | O2: 43 | P2: AB | Q2: 674 | R2: Elitech | S2: TCNTT | T2: Trường Công nghệ thông tin và Truyền thông | U2: 190467 | V2: D9-501 | W2: 67 | X2: =VLOOKUP(C2,VN_ICT!B:W,22,TRUE) -> Phạm Huy Hoàng
A3: 190468 | B3: 161250 | C3: 161250 | D3: IT4651 | E3: Thiết kế và triển khai mạng IP | F3: *Việt Nhật K67C | G3: 131 | H3: Nhóm 2 | I3: T21 | J3: Thứ sáu | K3: 46052 | L3: Kíp 4 | M3: Phòng máy TTMT | N3: 670 | O3: 42 | P3: AB | Q3: 674 | R3: Elitech | S3: TCNTT | T3: Trường Công nghệ thông tin và Truyền thông | U3: 190468 | V3: D9-501 | W3: 67 | X3: =VLOOKUP(C3,VN_ICT!B:W,22,TRUE) -> Phạm Huy Hoàng
A4: 190489 | B4: 161251 | C4: 161251 | D4: IT4785 | E4: Phát triển ứng dụng cho thiết bị di động | F4: *Việt Nhật K67-1C | G4: 131 | H4: Nhóm 2 | I4: T22 | J4: Thứ hai | K4: 46055 | L4: Kíp 3,5 | M4: Phòng máy TTMT | N4: 670 | O4: 51 | P4: AB | Q4: 674 | R4: Elitech | S4: TCNTT | T4: Trường Công nghệ thông tin và Truyền thông | U4: 190489 | V4: D9-501 | W4: 67 | X4: =VLOOKUP(C4,VN_ICT!B:W,22,TRUE) -> Lê Bá Vui
A5: 190490 | B5: 161251 | C5: 161251 | D5: IT4785 | E5: Phát triển ứng dụng cho thiết bị di động | F5: *Việt Nhật K67-1C | G5: 132 | H5: Nhóm 3 | I5: T22 | J5: Thứ hai | K5: 46055 | L5: Kíp 3,5 | M5: Phòng máy TTMT | N5: 670 | O5: 51 | P5: AB | Q5: 674 | R5: Elitech | S5: TCNTT | T5: Trường Công nghệ thông tin và Truyền thông | U5: 190490 | V5: D9-501 | W5: 67 | X5: =VLOOKUP(C5,VN_ICT!B:W,22,TRUE) -> Lê Bá Vui
A6: 190491 | B6: 161251 | C6: 161251 | D6: IT4785 | E6: Phát triển ứng dụng cho thiết bị di động | F6: *Việt Nhật K67-1C | G6: 130 | H6: Nhóm 1 | I6: T22 | J6: Thứ hai | K6: 46055 | L6: Kíp 3,5 | M6: Phòng máy TTMT | N6: 670 | O6: 52 | P6: AB | Q6: 674 | R6: Elitech | S6: TCNTT | T6: Trường Công nghệ thông tin và Truyền thông | U6: 190491 | V6: D9-501 | W6: 67 | X6: =VLOOKUP(C6,VN_ICT!B:W,22,TRUE) -> Lê Bá Vui
A7: 190493 | B7: 161252 | C7: 161252 | D7: IT4785 | E7: Phát triển ứng dụng cho thiết bị di động | F7: *Việt Nhật K67-2C | G7: 130 | H7: Nhóm 1 | I7: T22 | J7: Thứ hai | K7: 46055 | L7: Kíp 3,5 | M7: Phòng máy TTMT | N7: 670 | O7: 47 | P7: AB | Q7: 674 | R7: Elitech | S7: TCNTT | T7: Trường Công nghệ thông tin và Truyền thông | U7: 190493 | V7: D9-501 | W7: 67 | X7: =VLOOKUP(C7,VN_ICT!B:W,22,TRUE) -> Nguyễn Đình Thuận
A8: 190492 | B8: 161252 | C8: 161252 | D8: IT4785 | E8: Phát triển ứng dụng cho thiết bị di động | F8: *Việt Nhật K67-2C | G8: 131 | H8: Nhóm 2 | I8: T22 | J8: Thứ hai | K8: 46055 | L8: Kíp 3,5 | M8: Phòng máy TTMT | N8: 670 | O8: 47 | P8: AB | Q8: 674 | R8: Elitech | S8: TCNTT | T8: Trường Công nghệ thông tin và Truyền thông | U8: 190492 | V8: D9-501 | W8: 67 | X8: =VLOOKUP(C8,VN_ICT!B:W,22,TRUE) -> Nguyễn Đình Thuận
A9: 190494 | B9: 161252 | C9: 161252 | D9: IT4785 | E9: Phát triển ứng dụng cho thiết bị di động | F9: *Việt Nhật K67-2C | G9: 132 | H9: Nhóm 3 | I9: T22 | J9: Thứ hai | K9: 46055 | L9: Kíp 3,5 | M9: Phòng máy TTMT | N9: 670 | O9: 47 | P9: AB | Q9: 674 | R9: Elitech | S9: TCNTT | T9: Trường Công nghệ thông tin và Truyền thông | U9: 190494 | V9: D9-501 | W9: 67 | X9: =VLOOKUP(C9,VN_ICT!B:W,22,TRUE) -> Nguyễn Đình Thuận
A10: 190235 | B10: 161253 | C10: 161253 | D10: IT3190 | E10: Nhập môn Học máy và khai phá dữ liệu | F10: *Việt Nhật K67-1C | G10: 130 | H10: Nhóm 1 | I10: T21 | J10: Thứ hai | K10: 46048 | L10: Kíp 3,4 | M10: Phòng máy TTMT | N10: 670 | O10: 60 | P10: AB | Q10: 674 | R10: Elitech | S10: TCNTT | T10: Trường Công nghệ thông tin và Truyền thông | U10: 190235 | V10: D9-501 | W10: 67 | X10: =VLOOKUP(C10,VN_ICT!B:W,22,TRUE) -> Nguyễn Thị Kim Anh
A11: 190234 | B11: 161253 | C11: 161253 | D11: IT3190 | E11: Nhập môn Học máy và khai phá dữ liệu | F11: *Việt Nhật K67-1C | G11: 131 | H11: Nhóm 2 | I11: T21 | J11: Thứ hai | K11: 46048 | L11: Kíp 3,4 | M11: Phòng máy TTMT | N11: 670 | O11: 60 | P11: AB | Q11: 674 | R11: Elitech | S11: TCNTT | T11: Trường Công nghệ thông tin và Truyền thông | U11: 190234 | V11: D9-501 | W11: 67 | X11: =VLOOKUP(C11,VN_ICT!B:W,22,TRUE) -> Nguyễn Thị Kim Anh
A12: 190237 | B12: 161254 | C12: 161254 | D12: IT3190 | E12: Nhập môn Học máy và khai phá dữ liệu | F12: *Việt Nhật K67-2C | G12: 131 | H12: Nhóm 2 | I12: T21 | J12: Thứ hai | K12: 46048 | L12: Kíp 3,4 | M12: Phòng máy TTMT | N12: 670 | O12: 65 | P12: AB | Q12: 674 | R12: Elitech | S12: TCNTT | T12: Trường Công nghệ thông tin và Truyền thông | U12: 190237 | V12: D9-501 | W12: 67 | X12: =VLOOKUP(C12,VN_ICT!B:W,22,TRUE) -> Đỗ Tiến Dũng
A13: 190236 | B13: 161254 | C13: 161254 | D13: IT3190 | E13: Nhập môn Học máy và khai phá dữ liệu | F13: *Việt Nhật K67-2C | G13: 130 | H13: Nhóm 1 | I13: T21 | J13: Thứ hai | K13: 46048 | L13: Kíp 3,4 | M13: Phòng máy TTMT | N13: 670 | O13: 66 | P13: AB | Q13: 674 | R13: Elitech | S13: TCNTT | T13: Trường Công nghệ thông tin và Truyền thông | U13: 190236 | V13: D9-501 | W13: 67 | X13: =VLOOKUP(C13,VN_ICT!B:W,22,TRUE) -> Đỗ Tiến Dũng
... A19: 190412 | B19: 161257 | C19: 161257 | D19: IT4409 | E19: Công nghệ Web và dịch vụ trực tuyến | F19: *Việt Nhật K67 -3C | G19: 130 | H19: Nhóm 1 | I19: T20 | J19: Thứ hai | K19: 46041 | L19: Kíp 1,2 | M19: Phòng máy TTMT | N19: 670 | O19: 64 | P19: AB | Q19: 674 | R19: Elitech | S19: TCNTT | T19: Trường Công nghệ thông tin và Truyền thông | U19: 190412 | V19: D9-401 | W19: 67 | X19: =VLOOKUP(C19,VN_ICT!B:W,22,TRUE) -> Trịnh Tuấn Đạt
A20: 190345 | B20: 161258 | C20: 161258 | D20: IT4062 | E20: Thực hành Lập trình mạng | F20: *Việt Nhật K67-1S | G20: 365 | H20: TC | I20: Theo lịch của giáo viên | N20: 670 | O20: 39 | P20: AB | Q20: 674 | R20: Elitech | S20: TCNTT | T20: Trường Công nghệ thông tin và Truyền thông | U20: 190345 | V20: B1-204 | W20: 67 | X20: =VLOOKUP(C20,VN_ICT!B:W,22,TRUE) -> Bùi Trọng Tùng
A21: 190346 | B21: 161259 | C21: 161259 | D21: IT4062 | E21: Thực hành Lập trình mạng | F21: *Việt Nhật K67-2C | G21: 365 | H21: TC | I21: Theo lịch của giáo viên | N21: 670 | O21: 40 | P21: AB | Q21: 674 | R21: Elitech | S21: TCNTT | T21: Trường Công nghệ thông tin và Truyền thông | U21: 190346 | V21: B1-204 | W21: 67 | X21: =VLOOKUP(C21,VN_ICT!B:W,22,TRUE) -> Trương Thị Diệu Linh
A22: 190347 | B22: 161260 | C22: 161260 | D22: IT4062 | E22: Thực hành Lập trình mạng | F22: *Việt Nhật K67-3C | G22: 365 | H22: TC | I22: Theo lịch của giáo viên | N22: 670 | O22: 39 | P22: AB | Q22: 674 | R22: Elitech | S22: TCNTT | T22: Trường Công nghệ thông tin và Truyền thông | U22: 190347 | V22: B1-206 | W22: 67 | X22: =VLOOKUP(C22,VN_ICT!B:W,22,TRUE) -> Lã Thế Vinh
A23: 190348 | B23: 161261 | C23: 161261 | D23: IT4062 | E23: Thực hành Lập trình mạng | F23: *Việt Nhật K67-4S | G23: 365 | H23: TC | I23: Theo lịch của giáo viên | N23: 670 | O23: 40 | P23: AB | Q23: 674 | R23: Elitech | S23: TCNTT | T23: Trường Công nghệ thông tin và Truyền thông | U23: 190348 | V23: B1-204 | W23: 67 | X23: =VLOOKUP(C23,VN_ICT!B:W,22,TRUE) -> Đặng Tuấn Linh (0.5) - Trần Nguyên Ngọc (0.5)
A24: 190349 | B24: 161262 | C24: 161262 | D24: IT4062 | E24: Thực hành Lập trình mạng | F24: *Việt Nhật K67-5S | G24: 365 | H24: TC | I24: Theo lịch của giáo viên | N24: 670 | O24: 40 | P24: AB | Q24: 674 | R24: Elitech | S24: TCNTT | T24: Trường Công nghệ thông tin và Truyền thông | U24: 190349 | V24: B1-204 | W24: 67 | X24: =VLOOKUP(C24,VN_ICT!B:W,22,TRUE) -> Trương Thị Diệu Linh
A25: 190350 | B25: 161263 | C25: 161263 | D25: IT4062 | E25: Thực hành Lập trình mạng | F25: *Việt Nhật K67-6S | G25: 365 | H25: TC | I25: Theo lịch của giáo viên | N25: 670 | O25: 38 | P25: AB | Q25: 674 | R25: Elitech | S25: TCNTT | T25: Trường Công nghệ thông tin và Truyền thông | U25: 190350 | V25: B1-204 | W25: 67 | X25: =VLOOKUP(C25,VN_ICT!B:W,22,TRUE) -> Bùi Trọng Tùng
A26: 190351 | B26: 161264 | C26: 161264 | D26: IT4062 | E26: Thực hành Lập trình mạng | F26: *Việt Nhật K67-7S | G26: 365 | H26: TC | I26: Theo lịch của giáo viên | N26: 670 | O26: 38 | P26: AB | Q26: 674 | R26: Elitech | S26: TCNTT | T26: Trường Công nghệ thông tin và Truyền thông | U26: 190351 | V26: B1-206 | W26: 67 | X26: =VLOOKUP(C26,VN_ICT!B:W,22,TRUE) -> Trần Hải Anh
A27: 190352 | B27: 161265 | C27: 161265 | D27: IT4062 | E27: Thực hành Lập trình mạng | F27: *Việt Nhật K67-8S | G27: 365 | H27: TC | I27: Theo lịch của giáo viên | N27: 670 | O27: 40 | P27: AB | Q27: 674 | R27: Elitech | S27: TCNTT | T27: Trường Công nghệ thông tin và Truyền thông | U27: 190352 | V27: B1-204 | W27: 67 | X27: =VLOOKUP(C27,VN_ICT!B:W,22,TRUE) -> Trần Nguyên Ngọc
A28: 190353 | B28: 161266 | C28: 161266 | D28: IT4062 | E28: Thực hành Lập trình mạng | F28: *Việt Nhật K67-9S | G28: 365 | H28: TC | I28: Theo lịch của giáo viên | N28: 670 | O28: 40 | P28: AB | Q28: 674 | R28: Elitech | S28: TCNTT | T28: Trường Công nghệ thông tin và Truyền thông | U28: 190353 | V28: B1-204 | W28: 67 | X28: =VLOOKUP(C28,VN_ICT!B:W,22,TRUE) -> Đặng Tuấn Linh
A29: 190275 | B29: 161268 | C29: 161267 | D29: IT3323 | E29: Xây dựng chương trình dịch | F29: *Việt Nhật K67-1(BT)C | G29: 365 | H29: TC | I29: T22 | J29: Thứ ba | K29: 46056 | L29: Kíp 2 | M29: Phòng máy TTMT | N29: 670 | O29: 40 | P29: AB | Q29: 674 | R29: Elitech | S29: TCNTT | T29: Trường Công nghệ thông tin và Truyền thông | U29: 190275 | V29: B1-208 | W29: 67 | X29: =VLOOKUP(C29,VN_ICT!B:W,22,TRUE) -> Nguyễn Thị Thu Hương
A30: 190276 | B30: 161269 | C30: 161267 | D30: IT3323 | E30: Xây dựng chương trình dịch | F30: *Việt Nhật K67-2(BT)S | G30: 365 | H30: TC | I30: T22 | J30: Thứ ba | K30: 46056 | L30: Kíp 2 | M30: Phòng máy TTMT | N30: 670 | O30: 40 | P30: AB | Q30: 674 | R30: Elitech | S30: TCNTT | T30: Trường Công nghệ thông tin và Truyền thông | U30: 190276 | V30: B1-209 | W30: 67 | X30: =VLOOKUP(C30,VN_ICT!B:W,22,TRUE) -> Nguyễn Thị Thu Hương
A31: 190277 | B31: 161270 | C31: 161267 | D31: IT3323 | E31: Xây dựng chương trình dịch | F31: *Việt Nhật K67-3(BT)S | G31: 365 | H31: TC | I31: T22 | J31: Thứ ba | K31: 46056 | L31: Kíp 2 | M31: Phòng máy TTMT | N31: 670 | O31: 40 | P31: AB | Q31: 674 | R31: Elitech | S31: TCNTT | T31: Trường Công nghệ thông tin và Truyền thông | U31: 190277 | V31: B1-208 | W31: 67 | X31: =VLOOKUP(C31,VN_ICT!B:W,22,TRUE) -> Nguyễn Thị Thu Hương
A32: 190278 | B32: 161272 | C32: 161267 | D32: IT3323 | E32: Xây dựng chương trình dịch | F32: *Việt Nhật K67-4(BT)S | G32: 365 | H32: TC | I32: T22 | J32: Thứ ba | K32: 46056 | L32: Kíp 2 | M32: Phòng máy TTMT | N32: 670 | O32: 40 | P32: AB | Q32: 674 | R32: Elitech | S32: TCNTT | T32: Trường Công nghệ thông tin và Truyền thông | U32: 190278 | V32: B1-209 | W32: 67 | X32: =VLOOKUP(C32,VN_ICT!B:W,22,TRUE) -> Nguyễn Thị Thu Hương
A33: 190279 | B33: 161273 | C33: 161271 | D33: IT3323 | E33: Xây dựng chương trình dịch | F33: *Việt Nhật K67-5(BT)S | G33: 365 | H33: TC | I33: T22 | J33: Thứ ba | K33: 46056 | L33: Kíp 2 | M33: Phòng máy TTMT | N33: 670 | O33: 41 | P33: AB | Q33: 674 | R33: Elitech | S33: TCNTT | T33: Trường Công nghệ thông tin và Truyền thông | U33: 190279 | V33: B1-208 | W33: 67 | X33: =VLOOKUP(C33,VN_ICT!B:W,22,TRUE) -> Dương Quang Huy
A34: 190280 | B34: 161274 | C34: 161271 | D34: IT3323 | E34: Xây dựng chương trình dịch | F34: *Việt Nhật K67-6(BT)S | G34: 365 | H34: TC | I34: T22 | J34: Thứ ba | K34: 46056 | L34: Kíp 2 | M34: Phòng máy TTMT | N34: 670 | O34: 40 | P34: AB | Q34: 674 | R34: Elitech | S34: TCNTT | T34: Trường Công nghệ thông tin và Truyền thông | U34: 190280 | V34: B1-202 | W34: 67 | X34: =VLOOKUP(C34,VN_ICT!B:W,22,TRUE) -> Dương Quang Huy
A35: 190281 | B35: 161276 | C35: 161271 | D35: IT3323 | E35: Xây dựng chương trình dịch | F35: *Việt Nhật K67-7(BT)S | G35: 365 | H35: TC | I35: T22 | J35: Thứ ba | K35: 46056 | L35: Kíp 2 | M35: Phòng máy TTMT | N35: 670 | O35: 31 | P35: AB | Q35: 674 | R35: Elitech | S35: TCNTT | T35: Trường Công nghệ thông tin và Truyền thông | U35: 190281 | V35: B1-202 | W35: 67 | X35: =VLOOKUP(C35,VN_ICT!B:W,22,TRUE) -> Dương Quang Huy
A36: 190282 | B36: 161277 | C36: 161271 | D36: IT3323 | E36: Xây dựng chương trình dịch | F36: *Việt Nhật K67-8(BT)S | G36: 365 | H36: TC | I36: T22 | J36: Thứ ba | K36: 46056 | L36: Kíp 2 | M36: Phòng máy TTMT | N36: 670 | O36: 21 | P36: AB | Q36: 674 | R36: Elitech | S36: TCNTT | T36: Trường Công nghệ thông tin và Truyền thông | U36: 190282 | V36: B1-209 | W36: 67 | X36: =VLOOKUP(C36,VN_ICT!B:W,22,TRUE) -> Dương Quang Huy
A37: 190283 | B37: 161278 | C37: 161271 | D37: IT3323 | E37: Xây dựng chương trình dịch | F37: *Việt Nhật K67-9(BT)S | G37: 365 | H37: TC | I37: T22 | J37: Thứ ba | K37: 46056 | L37: Kíp 2 | M37: Phòng máy TTMT | N37: 670 | O37: 41 | P37: AB | Q37: 674 | R37: Elitech | S37: TCNTT | T37: Trường Công nghệ thông tin và Truyền thông | U37: 190283 | V37: B1-202 | W37: 67 | X37: =VLOOKUP(C37,VN_ICT!B:W,22,TRUE) -> Dương Quang Huy
A38: 190284 | B38: 161279 | C38: 161279 | D38: IT3362 | E38: Kỹ năng ITSS học bằng tiếng Nhật 1 | F38: *Việt Nhật K67-1S | G38: 365 | H38: TC | I38: Theo lịch của giáo viên | N38: 670 | O38: 40 | P38: AB | Q38: 674 | R38: Elitech | S38: TCNTT | T38: Trường Công nghệ thông tin và Truyền thông | U38: 190284 | V38: B1-203 | W38: 67 | X38: =VLOOKUP(C38,VN_ICT!B:W,22,TRUE) -> Kiyoshi Yorifuji
A39: 190285 | B39: 161280 | C39: 161280 | D39: IT3362 | E39: Kỹ năng ITSS học bằng tiếng Nhật 1 | F39: *Việt Nhật K67-2C | G39: 365 | H39: TC | I39: Theo lịch của giáo viên | N39: 670 | O39: 40 | P39: AB | Q39: 674 | R39: Elitech | S39: TCNTT | T39: Trường Công nghệ thông tin và Truyền thông | U39: 190285 | V39: B1-203 | W39: 67 | X39: =VLOOKUP(C39,VN_ICT!B:W,22,TRUE) -> Kiyoshi Yorifuji
A40: 190286 | B40: 161281 | C40: 161281 | D40: IT3362 | E40: Kỹ năng ITSS học bằng tiếng Nhật 1 | F40: *Việt Nhật K67-3S | G40: 365 | H40: TC | I40: Theo lịch của giáo viên | N40: 670 | O40: 40 | P40: AB | Q40: 674 | R40: Elitech | S40: TCNTT | T40: Trường Công nghệ thông tin và Truyền thông | U40: 190286 | V40: B1-203 | W40: 67 | X40: =VLOOKUP(C40,VN_ICT!B:W,22,TRUE) -> Kiyoshi Yorifuji
A41: 190287 | B41: 161282 | C41: 161282 | D41: IT3362 | E41: Kỹ năng ITSS học bằng tiếng Nhật 1 | F41: *Việt Nhật K67-4S | G41: 365 | H41: TC | I41: Theo lịch của giáo viên | N41: 670 | O41: 39 | P41: AB | Q41: 674 | R41: Elitech | S41: TCNTT | T41: Trường Công nghệ thông tin và Truyền thông | U41: 190287 | V41: B1-203 | W41: 67 | X41: =VLOOKUP(C41,VN_ICT!B:W,22,TRUE) -> Kimura Ryo
A42: 190288 | B42: 161283 | C42: 161283 | D42: IT3362 | E42: Kỹ năng ITSS học bằng tiếng Nhật 1 | F42: *Việt Nhật K67-5C | G42: 365 | H42: TC | I42: Theo lịch của giáo viên | N42: 670 | O42: 40 | P42: AB | Q42: 674 | R42: Elitech | S42: TCNTT | T42: Trường Công nghệ thông tin và Truyền thông | U42: 190288 | V42: B1-203 | W42: 67 | X42: =VLOOKUP(C42,VN_ICT!B:W,22,TRUE) -> Kiyoshi Yorifuji
A43: 190289 | B43: 161284 | C43: 161284 | D43: IT3362 | E43: Kỹ năng ITSS học bằng tiếng Nhật 1 | F43: *Việt Nhật K67-6C | G43: 365 | H43: TC | I43: Theo lịch của giáo viên | N43: 670 | O43: 34 | P43: AB | Q43: 674 | R43: Elitech | S43: TCNTT | T43: Trường Công nghệ thông tin và Truyền thông | U43: 190289 | V43: B1-203 | W43: 67 | X43: =VLOOKUP(C43,VN_ICT!B:W,22,TRUE) -> Kimura Ryo
A44: 190290 | B44: 161285 | C44: 161285 | D44: IT3362 | E44: Kỹ năng ITSS học bằng tiếng Nhật 1 | F44: *Việt Nhật K67-7C | G44: 365 | H44: TC | I44: Theo lịch của giáo viên | N44: 670 | O44: 40 | P44: AB | Q44: 674 | R44: Elitech | S44: TCNTT | T44: Trường Công nghệ thông tin và Truyền thông | U44: 190290 | V44: B1-204 | W44: 67 | X44: =VLOOKUP(C44,VN_ICT!B:W,22,TRUE) -> Kimura Ryo
A45: 190291 | B45: 161286 | C45: 161286 | D45: IT3362 | E45: Kỹ năng ITSS học bằng tiếng Nhật 1 | F45: *Việt Nhật K67-8C | G45: 365 | H45: TC | I45: Theo lịch của giáo viên | N45: 670 | O45: 40 | P45: AB | Q45: 674 | R45: Elitech | S45: TCNTT | T45: Trường Công nghệ thông tin và Truyền thông | U45: 190291 | V45: B1-203 | W45: 67 | X45: =VLOOKUP(C45,VN_ICT!B:W,22,TRUE) -> Kiyoshi Yorifuji
...

Sheet Tuan21
A1: Tuần 21 | D1: Thứ 2 (26.01.2026) | I1: Thứ 3 (27.01.2026) | N1: Thứ 4 (28.01.2026) | S1: Thứ 5 (29.01.2026) | X1: Thứ 6 (30.01.2026) | AC1: Thứ 7 | AG1: Chủ nhật
A2: TT | B2: Phòng | C2: Số sv | D2: Kíp 1 - 7h00 | E2: Kíp 2-9h30 | F2: Kíp 3-12h30 | G2: Kíp 4-15h00 | H2: Kíp 5-17h30 | I2: Kíp 1 - 7h00 | J2: Kíp 2-9h30 | K2: Kíp 3-12h30 | L2: Kíp 4-15h00 | M2: Kíp 5-17h30 | N2: Kíp 1 - 7h00 | O2: Kíp 2-9h30 | P2: Kíp 3-12h30 | Q2: Kíp 4-15h00 | R2: Kíp 5-17h30 | S2: Kíp 1 - 7h00 | T2: Kíp 2-9h30 | U2: Kíp 3-12h30 | V2: Kíp 4-15h00 | W2: Kíp 5-17h30 | X2: Kíp 1 - 7h00 | Y2: Kíp 2-9h30 | Z2: Kíp 3-12h30 | AA2: Kíp 4-15h00 | AB2: Kíp 5-17h30 | AC2: Kíp 1 | AD2: Kíp 2 | AE2: Kíp 3 | AF2: Kíp 4 | AG2: Kíp 1 | AH2: Kíp 2 | AI2: Kíp 3 | AJ2: Kíp 4
A3: 1 | B3: B1-106 | C3: 37 | D3: IT1108 | E3: IT1108 | F3: IT3190 - HaiPV | G3: IT4931 | H3: IT4263 | L3: IT4663 | M3: IT4015E | N3: IT3100 | O3: IT3100 | P3: IT3170 | Q3: IT3170E | R3: IT3170 | S3: IT4508E | U3: IT4785E | X3: IT3120 | Y3: IT3210 | Z3: IT3080E (NgocTN) | AA3: IT4651E | AB3: IT3080 (TungBT)
A4: 2 | B4: B1-107 | C4: 37 | D4: IT1108 | E4: IT1108 | F4: IT3190 - QuangNH | G4: IT4931 | H4: IT4263 | L4: IT4663 | M4: IT4015E | N4: IT3100 | O4: IT3100 | P4: IT3170 | Q4: IT3170E | R4: IT3170 | S4: IT4508E | U4: IT4785E | X4: IT3120 | Y4: IT3210 | Z4: IT3080E (DongLV) | AA4: IT4651E | AB4: IT3080 (TungBT)
A5: 3 | B5: B1-108 | C5: 37 | D5: IT1108 | E5: IT1108 | F5: IT3190 - TrinhVT | G5: IT4931 | H5: IT4263 | M5: IT4015E | N5: IT3100 | O5: IT3100 | P5: IT3170 | Q5: IT3170E | R5: IT3170 | X5: IT5412 (LinhNV) | Y5: IT3210 | Z5: IT3080E (DungHV) | AA5: IT4651 | AB5: IT3080 (TungBT)
A6: 4 | B6: B1-109 | C6: 37 | D6: IT1108 | E6: IT1108 | F6: IT3190 - HieuNK | G6: IT4931 | M6: IT4015 | N6: IT3100 | O6: IT3100 | P6: IT3170 | Q6: IT3170E | R6: IT3170 | X6: IT5412 (NamLH) | Y6: IT3210 | AA6: IT4651 | AB6: IT3080 (TungBT)
A7: 5 | B7: B1-202 | C7: 37 | D7: IT1108 | E7: IT1108 | F7: IT3190 - HauLD | G7: IT4931 | M7: IT4015 | N7: IT3100 | O7: IT3100 | P7: IT3170 | Q7: IT3170E | R7: IT3170 | W7: IT4142E | Y7: IT3160E | Z7: IT3080E (LinhTD) | AA7: IT4651 | AB7: IT3080
A8: 6 | B8: B1-203 -SD Laptop | C8: 30 | D8: IT1108 | E8: IT1108 | F8: IT3190 - TuanDQ | G8: IT4931 | O8: IT3100 | P8: IT3170 | Q8: IT3170E | AB8: IT3080
A9: 7 | B9: B1-204 | C9: 37 | D9: IT1108 | E9: IT1108 | F9: IT3190 - TrungTV | G9: IT4931 | M9: IT4015 | N9: IT3100 | O9: IT3100 | P9: IT3170 | Q9: IT3170 | R9: IT3170 | U9: IT3292E | W9: IT4142E | Y9: IT3160E | Z9: IT3080E (LinhTD) | AA9: IT4210 | AB9: IT3080
A10: 8 | B10: B1-206 | C10: 37 | D10: IT1108 | E10: IT1110E - TuanDQ | F10: IT3190 - Lương | G10: IT4931 | M10: IT4015 | N10: IT3100 | O10: IT3100 | P10: IT3170 | Q10: IT3170 | R10: IT3170 | U10: IT3292E | V10: IT4788 | W10: IT4142E | X10: IT3280E | Y10: IT3160E | Z10: IT3080E (LyDTH) | AA10: IT4210 | AB10: IT3080
A11: 9 | B11: B1-207 | C11: 37 | D11: IT1108 | E11: IT1110E - TuanDQ | F11: IT3190 - Duy | G11: IT4931 | M11: IT4015 | N11: IT3100 | O11: IT3100 | P11: IT3170 | Q11: IT3170 | R11: IT3170 | U11: IT3292E | V11: IT4788 | W11: IT4142E | X11: IT3280E - TienND | Y11: IT3160E | Z11: IT3080E (LyDTH) | AA11: IT4651 | AB11: IT3080
A12: 10 | B12: B1-208 | C12: 37 | D12: IT1108 | E12: IT1110E - ThieuVV | F12: IT3190 - AnhNK | G12: IT3190 - AnhNK | M12: IT4015 | N12: IT5411-LTHuong | O12: IT3100 | P12: IT3170 | Q12: IT3170 | R12: IT3170 | U12: IT3292E | V12: IT4788 | W12: IT4142E -Khoat | X12: IT3280E | Y12: IT3160E | Z12: IT3080E (LyDTH) | AA12: IT4651 | AB12: IT3080
A13: 11 | B13: B1-209 | C13: 37 | D13: IT1108 | E13: IT1110E - AnhDT | F13: IT3190 - DungDT | G13: IT3190 - DungDT | M13: IT4015 | N13: IT5411-NSTung | O13: IT3100 | P13: IT3170 | Q13: IT3170 | R13: IT3170 | U13: IT3292E | V13: IT4788 | W13: IT4142E -TungND | X13: IT3280E | Y13: IT3160E | Z13: IT3080E | AA13: IT4651 | AB13: IT3080
D14: =COUNTA(D3:D13) -> 11 | E14: =COUNTA(E3:E13) -> 11 | F14: =COUNTA(F3:F13) -> 11 | G14: =COUNTA(G3:G11) -> 9 | H14: =COUNTA(H3:H13) -> 3 | I14: =COUNTA(I3:I13) -> 0 | J14: =COUNTA(J3:J13) -> 0 | K14: =COUNTA(K3:K13) -> 0 | L14: =COUNTA(L3:L13) -> 2 | M14: =COUNTA(M3:M13) -> 10 | N14: =COUNTA(N3:N13) -> 10 | O14: =COUNTA(O3:O13) -> 11 | ... T14: =COUNTA(T3:T13) -> 0 | U14: =COUNTA(U5:U13) -> 5 | V14: =COUNTA(V7:V13) -> 4 | W14: =COUNTA(W7:W13) -> 6 | X14: =COUNTA(X3:X13) -> 8 | Y14: =COUNTA(Y3:Y13) -> 10 | Z14: =COUNTA(Z3:Z13) -> 9 | AB14: =COUNTA(AB3:AB13) -> 11 | AC14: =COUNTA(AC3:AC13) -> 0 | AD14: =COUNTA(AD3:AD13) -> 0 | AE14: =COUNTA(AE3:AE13) -> 0 | AF14: =COUNTA(AF3:AF13) -> 0 | AG14: =COUNTA(AG3:AG13) -> 0 | AH14: =COUNTA(AH3:AH13) -> 0 | AI14: =COUNTA(AI3:AI13) -> 0 | AJ14: =COUNTA(AJ3:AJ13) -> 0
B15: Số sv thi | D15: =(11-D14)*37-5 -> -5 | E15: =(11-E14)*37-5 -> -5 | F15: =(11-F14)*37-5 -> -5 | G15: =(11-G14)*37-5 -> 69 | H15: =(11-H14)*37-5 -> 291 | I15: =(11-I14)*37-5 -> 402 | J15: =(11-J14)*37-5 -> 402 | K15: =(11-K14)*37-5 -> 402 | ... Z15: =(11-Z14)*37-5 -> 69 | AB15: =(11-AB14)*37-5 -> -5 | AC15: =(11-AC14)*37-5 -> 402 | AD15: =(11-AD14)*37-5 -> 402 | AE15: =(11-AE14)*37-5 -> 402 | AF15: =(11-AF14)*37-5 -> 402 | AG15: =(11-AG14)*37-5 -> 402 | AH15: =(11-AH14)*37-5 -> 402 | AI15: =(11-AI14)*37-5 -> 402 | AJ15: =(11-AJ14)*37-5 -> 402
A17: Trực kỹ thuật | D17: Hustack | E17: Hustack | L17: Hustack | P17: Hustack | Q17: Hustack | R17: Hustack
B18: Tầng 1 | D18: Trần Thị Dung | F18: Lê Thị Hoa | K18: Phạm Quang Hiếu | N18: Nguyễn Văn Hiên | P18: Phạm Quang Hiếu | S18: Phạm Thị Phương Giang | U18: Phạm Thanh Liêm | X18: Nhữ Thị Nga | Z18: Phạm Thị Phương Giang
B19: Tầng 2 | D19: Nguyễn Văn Hiên | F19: Phạm Quang Hiếu | K19: Lê Thị Hoa | N19: Nhữ Thị Nga | P19: Nguyễn Văn Hiên | U19: Phạm Thị Phương Giang | X19: Phạm Thị Phương Giang | Z19: Nhữ Thị Nga

Sheet Tuan22
A1: Tuần 22 | D1: Thứ 2 (02.02.2026) | I1: Thứ 3 (3.2.2026) | N1: Thứ 4 (4.2.2026) | U1: Thứ 5 (5.2.2026) | Z1: Thứ 6 (6.2.2026) | AE1: Thứ 7 (7.2.2026) | AK1: Chủ nhật (8.2.2026)
A2: TT | B2: Phòng | C2: Số sv | D2: Kíp 1 | E2: Kíp 2 | F2: Kíp 3 | G2: Kíp 4 | H2: Kíp 5 | I2: Kíp 1 | J2: Kíp 2 | K2: Kíp 3 | L2: Kíp 4 | M2: Kíp 5 | N2: Kíp 1.1 | O2: Kíp 1.2 | P2: Kíp 2.1 | Q2: Kíp 2.2 | R2: Kíp 3 | S2: Kíp 4 | T2: Kíp 5 | U2: Kíp 1 | V2: Kíp 2 | W2: Kíp 3 | X2: Kíp 4 | Y2: Kíp 5 | Z2: Kíp 1 | AA2: Kíp 2 | AB2: Kíp 3 | AC2: Kíp 4 | AD2: Kíp 5 | AE2: Kíp 1 | AF2: Kíp 2 | AG2: Kíp 3 (12h20) | AI2: Kíp 4 (15h00) | AK2: Kíp 1 (7h) | AL2: Kíp 2 (8h10) | AM2: Kíp 3 (9h20) | AN2: Kíp 4 (10h40) | AO2: Kíp 5 (13h) | AP2: Kíp 6 (14h10) | AQ2: Kíp 7 (15h20) | AR2: Kíp 8 (16h30)
A3: 1 | B3: B1-106 | C3: 37 | D3: IT3320E KhoatTQ | E3: IT3420 | F3: IT3160-TDKhang | G3: IT4785 | H3: IT4785 | I3: IT3323 | N3: IT2000 - ĐồngLV | O3: IT2000 - ĐồngLV | P3: IT2000 - ĐồngLV | Q3: IT2000 - ĐồngLV | R3: IT3011 | S3: IT4815E | T3: IT3011 | U3: IT5409 | X3: IT4593 | Y3: IT4593 | Z3: IT4244 - TrungLĐ | AA3: IT3070 | AB3: IT3070 | AC3: IT3070 | AG3: IT1130-NgaNT | AH3: 756922 | AI3: IT1130-NgaNT | AJ3: 756921 | AK3: IT1140 | AL3: IT1140 | AM3: IT1140 | AN3: IT1140 | AO3: IT1140 | AP3: IT1140 | AQ3: IT1140 | AR3: IT1140
A4: 2 | B4: B1-107 | C4: 37 | D4: IT3320E TungND | E4: IT3420 | F4: IT3160 | G4: IT4785 | H4: IT4785 | I4: IT3323 | N4: IT2000 | O4: IT2000 | P4: IT2000 | Q4: IT2000 | R4: IT3011 | S4: IT4815E | T4: IT3011 | X4: IT4593 | Y4: IT4593 | Z4: IT4244 - TienND | AA4: IT3070 | AB4: IT3070 | AC4: IT3070 | AG4: IT1130-NgaNT | AH4: 756924 | AI4: IT1130-NgaNT | AJ4: 756923 | AK4: IT1140 | AL4: IT1140 | AM4: IT1140 | AN4: IT1140 | AO4: IT1140 | AP4: IT1140 | AQ4: IT1140 | AR4: IT1140
A5: 3 | B5: B1-108 | C5: 37 | D5: IT3320E | E5: IT3420 | F5: IT3160 | G5: IT4785 | H5: IT4785 | I5: IT3323 | N5: IT2000 | O5: IT2000 | P5: IT2000 | Q5: IT2000 | R5: IT3011 | S5: IT3011 | T5: IT3011 | W5: IT4593 | X5: IT4593 | Y5: IT4593 | Z5: IT4244 - HaiNN | AA5: IT3070 | AB5: IT3070 | AC5: IT3070 | AG5: IT1130-NgaNT | AH5: 756916 | AI5: IT1130-NgaNT | AJ5: 756915 | AK5: IT1140 | AL5: IT1140 | AM5: IT1140 | AN5: IT1140 | AO5: IT1140 | AP5: IT1140 | AQ5: IT1140 | AR5: IT1140
A6: 4 | B6: B1-109 | C6: 37 | D6: IT3320E | E6: IT3420 | F6: IT3160 | G6: IT4785 | H6: IT4785 | I6: IT3323 | N6: IT2000 | O6: IT2000 | P6: IT2000 | Q6: IT2000 | R6: IT3011 | S6: IT4653 | T6: IT3011 | W6: IT4593 | X6: IT4593 | Y6: IT4593 | Z6: IT4244 - TuanNM | AA6: IT3070 | AB6: IT3070 | AC6: IT3070 | AK6: IT1140 | AL6: IT1140 | AM6: IT1140 | AN6: IT1140 | AO6: IT1140 | AP6: IT1140 | AQ6: IT1140 | AR6: IT1140
A7: 5 | B7: B1-202 | C7: 37 | D7: IT3320E | E7: IT3420 | F7: IT4785 | G7: IT4785 | H7: IT4785 | I7: IT3323 | L7: IT4490 | R7: IT3011 | S7: IT4653 | T7: IT3011 | W7: IT4593 | X7: IT4593E | Y7: IT4593 | AA7: IT3100E | AB7: IT4010E | AC7: IT3070 | AK7: IT1110Q | AL7: IT1140 | AM7: IT1140 | AN7: IT1140 | AO7: IT1140 | AP7: IT1140 | AQ7: IT1140 | AR7: IT1140
A8: 6 | B8: B1-203 -SD Laptop | C8: 30 | F8: IT4785 | G8: IT4785 | H8: IT4785 | R8: IT3011Q | S8: IT4653 | AA8: IT3100E | AB8: IT4010E | AL8: IT1140 | AM8: IT1140 | AN8: IT1140 | AO8: IT1140 | AP8: IT1140 | AQ8: IT1140 | AR8: IT1140
A9: 7 | B9: B1-204 | C9: 37 | E9: IT3420 | F9: IT3160 | G9: IT4785 | H9: IT4785E | I9: IT3323 | L9: IT4490 | N9: IT2000 | O9: IT2000 | P9: IT2000 | Q9: IT2000 | R9: IT3011 | S9: IT4653 | T9: IT3011 | U9: IT3020E | W9: IT4593 | X9: IT4593E | Y9: IT4593 | AA9: IT3100E | AB9: IT4010E | AG9: IT1130-DungTT | AH9: 756917 | AK9: IT1110Q | AL9: IT1140 | AM9: IT1140 | AN9: IT1140 | AO9: IT1140 | AP9: IT1140 | AQ9: IT1140 | AR9: IT1140
A10: 8 | B10: B1-206 | C10: 37 | E10: IT3420 | F10: IT3160-DTDung | G10: IT4785 | H10: IT4785E | I10: IT3323 | L10: IT4490 | N10: IT2000 | O10: IT2000 | P10: IT2000 | Q10: IT2000 | R10: IT3011 | S10: IT4653 | T10: IT3011 | U10: IT3020E | W10: IT4593 | X10: IT4613 - Linh NV | Y10: IT4593 | AA10: IT3100E | AB10: IT4010E | AG10: IT1130-DungTT | AH10: 756920 | AK10: IT1110Q | AL10: IT1140 | AM10: IT1140 | AN10: IT1140 | AO10: IT1140 | AP10: IT1140 | AQ10: IT1140 | AR10: IT1140
A11: 9 | B11: B1-207 | C11: 37 | E11: IT3420 | F11: IT3160-DQTuan | G11: IT4785 | H11: IT4785E | I11: IT3323 | L11: IT4490 | N11: IT2000 | O11: IT2000 | P11: IT2000 | Q11: IT2000 | R11: IT3011E | S11: IT4653 | T11: IT3011 | U11: IT3020E | W11: IT4593 | X11: IT4613 - NamLH | Y11: IT4593 | AA11: IT3100E | AB11: IT4010E | AC11: IT4868E | AG11: IT1130-DungTT | AH11: 756919 | AK11: IT1110Q | AL11: IT1140 | AM11: IT1140 | AN11: IT1140 | AO11: IT1140 | AP11: IT1140 | AQ11: IT1140 | AR11: IT1140
A12: 10 | B12: B1-208 | C12: 37 | E12: IT3420 | F12: IT3160 - LTHuong | G12: IT4785 | H12: IT4785E | I12: IT3323 | L12: IT4490 | N12: IT2000 | O12: IT2000 | P12: IT2000 | Q12: IT2000 | R12: IT3011E | S12: IT4653 | T12: IT3011 | U12: IT3020E | W12: IT4593 | X12: IT4613 - TungNS | Y12: IT4593 | AA12: IT3100E | AB12: IT4010E | AC12: IT4868E | AG12: IT1130-HoaLT | AH12: 756918 | AK12: IT1110Q | AL12: IT1140 | AM12: IT1140 | AN12: IT1140 | AO12: IT1140 | AP12: IT1140 | AQ12: IT1140 | AR12: IT1140
A13: 11 | B13: B1-209 | C13: 37 | E13: IT3420 | F13: IT3160-dự phòng | G13: IT4785 | H13: IT4785E | I13: IT3323 | L13: IT4490 | N13: IT2000 | O13: IT2000 | P13: IT2000 | Q13: IT2000 | R13: IT3011E | S13: IT4653 | U13: IT3020E | W13: IT4593 | X13: IT4613 - LuongHDV | Y13: IT4593 | AA13: IT3100E | AB13: IT4010E | AC13: IT4868E | AG13: IT1130-HoaLT | AH13: 756925 | AK13: IT1110Q | AL13: IT1140 | AM13: IT1140 | AN13: IT1140 | AO13: IT1140 | AP13: IT1140 | AQ13: IT1140 | AR13: IT1140
D14: =COUNTA(D3:D13) -> 5 | E14: =COUNTA(E3:E13) -> 10 | F14: =COUNTA(F3:F13) -> 11 | G14: =COUNTA(G3:G13) -> 11 | H14: =COUNTA(H3:H13) -> 11 | I14: =COUNTA(#REF!) -> 1 | J14: =COUNTA(I3:I13) -> 10 | K14: =COUNTA(K3:K13) -> 0 | L14: =COUNTA(L3:L13) -> 6 | M14: =COUNTA(#REF!) -> 1 | N14: =COUNTA(N3:N13) -> 9 | P14: =COUNTA(P3:P13) -> 9 | R14: =COUNTA(T3:T13) -> 9 | S14: =COUNTA(S3:S13) -> 11 | T14: =COUNTA(Q3:Q13) -> 9 | U14: =COUNTA(U3:U13) -> 6 | V14: =COUNTA(V3:V13) -> 0 | W14: =COUNTA(W3:W13) -> 8 | X14: =COUNTA(X3:X13) -> 10 | Y14: =COUNTA(Y3:Y13) -> 10 | Z14: =COUNTA(Z3:Z13) -> 4 | AA14: =COUNTA(AA3:AA13) -> 11 | AB14: =COUNTA(AB3:AB13) -> 11 | AD14: =COUNTA(#REF!) -> 1 | AE14: =COUNTA(AE3:AE10) -> 0 | AF14: =COUNTA(AF3:AF10) -> 0 | AG14: =COUNTA(AG5:AG8) -> 1 | AH14: =COUNTA(AH3:AH6) -> 3 | AK14: =COUNTA(AK3:AK13) -> 10 | AL14: =COUNTA(AL3:AL13) -> 11 | AM14: =COUNTA(AM3:AM13) -> 11 | AN14: =COUNTA(AN3:AN13) -> 11 | AO14: =COUNTA(AO3:AO13) -> 11 | AP14: =COUNTA(AP3:AP13) -> 11 | AQ14: =COUNTA(AQ3:AQ13) -> 11 | AR14: =COUNTA(AR3:AR13) -> 11
B15: Số sv thi | D15: =(11-D14)*37-5 -> 217 | E15: =(11-E14)*37-5 -> 32 | F15: =(11-F14)*37-5 -> -5 | G15: =(11-G14)*37-5 -> -5 | H15: =(11-H14)*37-5 -> -5 | I15: =(11-I14)*37-5 -> 365 | J15: =(11-J14)*37-5 -> 32 | K15: =(11-K14)*37-5 -> 402 | ... N15: =(11-N14)*37-5 -> 69 | P15: =(11-P14)*37-5 -> 69 | R15: =(11-R14)*37-5 -> 69 | S15: =(11-S14)*37-5 -> -5 | T15: =(11-T14)*37-5 -> 69 | U15: =(11-U14)*37-5 -> 180 | V15: =(11-V14)*37-5 -> 402 | W15: =(11-W14)*37-5 -> 106 | X15: =(11-X14)*37-5 -> 32 | Y15: =(11-Y14)*37-5 -> 32 | ... AB15: =(11-AB14)*37-5 -> -5 | AD15: =(11-AD14)*37-5 -> 365 | AE15: =(11-AE14)*37-5 -> 402 | AF15: =(11-AF14)*37-5 -> 402
A17: Trực kỹ thuật | AK17: Sáng Chủ nhật 8.02.2026 | AO17: Chiều chủ nhật 8.02.2026
B18: Tầng 1 | D18: Nhữ Thị Nga | F18: Trần Thị Dung | I18: Lê Thị Hoa | N18: Nhữ Thị Nga | R18: Phạm Quang Hiếu | U18: Phạm Thị Phương Giang | W18: Nguyễn Văn Hiên | Z18: Nhữ Thị Nga | AB18: Trần Thị Dung | AG18: Nhữ Thị Nga | AH18: Lê Thị Hoa | AK18: Nhữ Thị Nga | AL18: Phạm Thanh Liêm | AM18: Nguyễn An Hưng | AO18: Lê Thị Hoa | AP18: Nguyễn An Hưng | AQ18: Phạm Thanh Liêm
B19: Tầng 2 | D19: Trần Thị Dung | F19: Lê Thị Hoa | I19: Trần Thị Dung | K19: Trần Thị Dung | N19: Phạm Quang Hiếu | R19: Nhữ Thị Nga | U19: Phạm Thanh Liêm | W19: Phạm Thị Phương Giang | Z19: Phạm Thị Phương Giang | AB19: Phạm Thị Phương Giang | AG19: Trần Thị Ding | AK19: Trần Thị Dung | AL19: Phạm Quang Hiếu | AM19: Hoàng Văn Hiệp | AO19: Phạm Thị Phương Giang | AP19: Hoàng Văn Hiệp | AQ19: Nguyễn Văn Hiên

Sheet Phân công coi thi
D1: DANH SÁCH PHÂN CÔNG COI THI CÁC LỚP THI TRÊN PHÒNG MÁY TÍNH
D2: KỲ | E2: 2025.1
D3: Giờ thi: Kíp 1 (7h00) - Kíp 2 (9h30) - Kíp 3 (12h30) - Kíp 4 (15h00) - Kíp 5 (17h30)
A6: STT | B6: Mã lớp thi | C6: Mã lớp | D6: Mã học phần | E6: Tên học phần | F6: Tuần thi | G6: Thứ | H6: Ngày thi | I6: Kíp thi | J6: Phòng thi | K6: Số lượng sinh viên/1 lớp thi | L6: Cán bộ coi thi | M6: Giảng viên phụ trách | N6: Trực cam
A7: =ROW()-6 -> 1 | D7: IT3030E | E7: Computer Architecture | F7: 20 | G7: 4 | H7: 46043 | I7: 1 | J7: B1-106 | K7: 33 | L7: Hoàng Văn Hiệp | M7: Nguyễn Đức Tiến
A8: =ROW()-6 -> 2 | D8: IT3030E | E8: Computer Architecture | F8: 20 | G8: 4 | H8: 46043 | I8: 1 | J8: B1-107 | K8: 32 | L8: Nguyễn Đức Tiến | M8: Nguyễn Đức Tiến
A9: =ROW()-6 -> 3 | D9: IT3030E | E9: Computer Architecture | F9: 20 | G9: 4 | H9: 46043 | I9: 1 | J9: B1-108 | K9: 31 | L9: Trần Duy | M9: Nguyễn Đức Tiến
A10: =ROW()-6 -> 4 | D10: IT3030E | E10: Computer Architecture | F10: 20 | G10: 4 | H10: 46043 | I10: 2 | J10: B1-106 | K10: 32 | L10: Ngô Lam Trung | M10: Nguyễn Đức Tiến
A11: =ROW()-6 -> 5 | D11: IT3030E | E11: Computer Architecture | F11: 20 | G11: 4 | H11: 46043 | I11: 2 | J11: B1-107 | K11: 32 | L11: Nguyễn Đức Tiến | M11: Nguyễn Đức Tiến
A12: =ROW()-6 -> 6 | D12: IT3030E | E12: Computer Architecture | F12: 20 | G12: 4 | H12: 46043 | I12: 2 | J12: B1-108 | K12: 32 | L12: Trần Duy | M12: Nguyễn Đức Tiến
A13: =ROW()-6 -> 7 | D13: IT3030E | E13: Computer Architecture | F13: 20 | G13: 4 | H13: 46043 | I13: 2 | J13: B1-109 | K13: 22 | L13: Đỗ Công Thuần | M13: Nguyễn Đức Tiến
A14: =ROW()-6 -> 8 | D14: IT3280E | E14: Computer Architecture | F14: 20 | G14: 4 | H14: 46043 | I14: 4 | J14: B1-204 | K14: 31 | L14: Phạm Ngọc Hưng | M14: Nguyễn Đức Tiến
A15: =ROW()-6 -> 9 | D15: IT3280E | E15: Computer Architecture | F15: 20 | G15: 4 | H15: 46043 | I15: 4 | J15: B1-206 | K15: 31 | L15: Dương Hữu Huynh | M15: Nguyễn Đức Tiến
A16: =ROW()-6 -> 10 | D16: IT3280E | E16: Computer Architecture | F16: 20 | G16: 4 | H16: 46043 | I16: 4 | J16: B1-207 | K16: 32 | L16: Nguyễn Đức Tiến | M16: Nguyễn Đức Tiến
A17: =ROW()-6 -> 11 | D17: IT3280E | E17: Computer Architecture | F17: 20 | G17: 4 | H17: 46043 | I17: 4 | J17: B1-208 | K17: 28 | L17: Hoàng Văn Hiệp | M17: Nguyễn Đức Tiến
A18: =ROW()-6 -> 12 | D18: IT3280E | E18: Computer Architecture | F18: 20 | G18: 4 | H18: 46043 | I18: 4 | J18: B1-209 | K18: 31 | L18: Nguyễn Hoàng Long | M18: Nguyễn Đức Tiến
... A37: =ROW()-6 -> 31 | D37: IT3030 | E37: Kiến trúc Máy tính | F37: 20 | G37: 4 | H37: 46043 | I37: 5.2 | J37: B1-209 | K37: 38 | L37: Ngô Thành Trung | M37: Nguyễn Đức Tiến
A38: =ROW()-6 -> 32 | D38: IT2000 | E38: Nhập môn CNTT&TT | F38: 22 | G38: 4 | H38: 46114 | I38: 1 | J38: B1-106 | K38: 32 | M38: Nguyễn Đức Tiến
A39: =ROW()-6 -> 33 | D39: IT2000 | E39: Nhập môn CNTT&TT | F39: 22 | G39: 4 | H39: 46114 | I39: 1 | J39: B1-107 | K39: 32 | M39: Nguyễn Đức Tiến
A40: =ROW()-6 -> 34 | D40: IT2000 | E40: Nhập môn CNTT&TT | F40: 22 | G40: 4 | H40: 46114 | I40: 1 | J40: B1-108 | K40: 32 | M40: Nguyễn Đức Tiến
A41: =ROW()-6 -> 35 | D41: IT2000 | E41: Nhập môn CNTT&TT | F41: 22 | G41: 4 | H41: 46114 | I41: 1 | J41: B1-109 | K41: 32 | M41: Nguyễn Đức Tiến
A42: =ROW()-6 -> 36 | D42: IT2000 | E42: Nhập môn CNTT&TT | F42: 22 | G42: 4 | H42: 46114 | I42: 1 | J42: B1-204 | K42: 32 | M42: Nguyễn Đức Tiến
A43: =ROW()-6 -> 37 | D43: IT2000 | E43: Nhập môn CNTT&TT | F43: 22 | G43: 4 | H43: 46114 | I43: 1 | J43: B1-206 | K43: 32 | M43: Nguyễn Đức Tiến
A44: =ROW()-6 -> 38 | D44: IT2000 | E44: Nhập môn CNTT&TT | F44: 22 | G44: 4 | H44: 46114 | I44: 1 | J44: B1-207 | K44: 32 | M44: Nguyễn Đức Tiến
A45: =ROW()-6 -> 39 | D45: IT2000 | E45: Nhập môn CNTT&TT | F45: 22 | G45: 4 | H45: 46114 | I45: 1 | J45: B1-208 | K45: 32 | M45: Nguyễn Đức Tiến
